Workbook

Sheet 읽어보기
A1: SeD팀 과제 1 (조업형태 분류) 피처 카탈로그
A2: 작성 2026-10-27 · 코드 model/feature_taxonomy.py, make_feature_catalog.py · 모든 수치는 선박 단위 5-fold 교차검증(rfid_id 기준 분리) 결과
A3: 팀원 4명(지유·민성·나연·진우)의 피처 명세와 진행1 §6 가설(A~H)을 하나의 파이프라인(model/)으로 다시 구현한 피처 전체 목록입니다.
A5: 1. 왜 피처가 346개인가: 데이터 흐름
A6: 단계 | B6: 1행의 단위 | C6: 피처 수 | D6: 어떻게 만드나 | E6: 코드 | F6: 시트
A7: L1 시간 | B7: 선박·날짜·시간대 | C7: 92 | D7: 1시간 항적(MultiLineString) 하나에서 직접 계산. 튐 제거·평활 등 정제 후 | E7: fe_hourly.py | F7: 시간단위_L1
A8: L2 선박-일 | B8: 선박·날짜 | C8: 101 | D8: 하루의 시간대들을 요약 + '이동 시간대'만 평균낸 mv_* 44개 | E8: fe_aggregate.py | F8: 일단위_MIL
A9: L3 선박 | B9: 선박 | C9: 346 | D9: 출어일 값들의 평균·중앙값·표준편차(+일부 90% 분위) + 조업 시간대 풀링 + 선박 전용 → 분류 모델 입력 | E9: fe_aggregate.py | F9: 선박피처
A10: → 서로 다른 '기본 피처'는 134종뿐. 같은 기본 피처에 통계(평균/중앙값/표준편차…)를 여러 개 붙이면서 346개가 됨.
A11: → 같은 기본 피처에서 나온 '형제 피처'는 선박피처 시트의 '기본 피처' 열로 필터해서 함께 볼 수 있습니다.
A13: 2. Pool A / Pool B: 위치 피처를 넣느냐 빼느냐
A14: 구분 | B14: 포함 피처 | C14: 후보 수 | D14: 목적 | E14: 선정 결과(k*) | F14: 최고 macro-F1
A15: Pool A | B15: 위치 7개 제외 | C15: 339 | D15: 순수 조업 '행동'만으로 판별 → 처음 보는 해역의 선박에도 통하는 모델 | E15: 중복 제거 후 전부 (250개) | F15: 0.523 (앙상블+보정)
A16: Pool B | B16: 위치 포함 | C16: 346 | D16: 대회 점수 극대화 (어느 바다에서 조업하는지도 활용) | E16: 상위 30개 | F16: 0.540 (앙상블)
A17: 왜 나누나: 위치를 넣으면 F1이 오르지만, 모델이 '조업 방식'이 아니라 '어느 지역 배인가'를 외우는 shortcut 위험이 있음 (HANDOFF §3.3). 그래서 두 모델을 항상 같이 보고.
A18: 위치 피처 7개: lon_c, lat_c, home_lon, home_lat, home_port_km, fishing_lon, fishing_lat (선박피처 시트 '위치(LOC)' = O)
A19: Pool A가 피처를 줄이지 않은 이유: 위치를 빼면 신호가 약한 피처 여러 개에 얇게 퍼져 있어, 줄일수록 1 표준오차 넘게 성능이 떨어짐 (k=60 0.447 < 전체 0.461).
A21: 3. 분류 체계: 대분류 12 → 세부 구분 → 기본 피처 → 선박 피처
A22: 대분류 12개, 세부 구분 37개. 범주는 사람이 읽기 위한 이름표이고 모델에는 쓰이지 않음 (피처 하나하나를 따로 순위 매김).
A23: 출처: 팀원 명세의 그룹(민성 공간/방향/속도/시간, 나연 v2 사전 그룹, 지유 ①~⑦) + 진행1 §6 가설 그룹을 합쳐 정리. 전체 구조는 '범주구조' 시트.
A24: 가설 표시 | B24: 뜻 (진행1 §6 자망 vs 연안복합)
A25: A | B25: 재방문: 자망은 어구를 놓고 떠났다가 같은 자리로 돌아와 회수
A26: B | B26: 직선 투망: 그물을 수백 m~수 km 직선으로 펼침
A27: C | B27: 속도 구조: 양망 시 긴 극저속, 업종별 속도 조합
A28: D | B28: 선회: 루프·톱니형 재이동
A29: E | B29: 하루 리듬: 투망-휴식-양망 블록 구조, 조업 시각
A30: G | B30: 선박 내 이질성: 날마다 다른 어구 사용 (날짜 간 표준편차, 출어일 유형)
A31: H | B31: 계절: 월별 조업 패턴
A32: (F) | B32: 지역 → 위치(LOC) 피처로 별도 관리
A34: 4. 피처 이름 읽는 법
A35: 표기 | B35: 뜻 | C35: 예시
A36: mv_XXX_mean / _median / _std | B36: 출어일마다 '이동 시간대'의 XXX 평균을 구한 뒤 → 출어일들의 평균 / 중앙값 / 표준편차(날마다 얼마나 다른가) | C36: mv_turn_mean_median
A37: XXX_mean / _median / _std | B37: 하루 단위 값 XXX 의 출어일 평균 / 중앙값 / 표준편차 | C37: longest_streak_mean
A38: XXX_p90 | B38: 출어일 값의 90% 분위 (많이 나간 날 기준) | C38: dist_day_km_p90
A39: fh_XXX_q50 / _q90 | B39: 조업 시간대(이동 중 & 항해 아님) 1시간 값들의 선박별 중앙값 / 90% 분위 (민성 C) | C39: fh_pca_elong_q90
A40: ks_ | B40: 5개 점 간격(k-step)으로 잰 지터 강건 버전 (민성) | C40: ks_speed_med
A41: _sea | B41: 항구 정박 시간을 뺀 나머지 시간 기준 비율 (민성 H4) | C41: drift_share_sea
A42: _share / _ratio / _frac | B42: 비율 (0~1) | C42: port_share
A43: _m / _km / _kn / _h | B43: 단위: 미터 / 킬로미터 / 노트 / 시간 | C43: home_km_max
A45: 5. 피처 선정 방식 (모두 fold 안의 학습 데이터로만 계산 → 검증 선박 정보 누수 없음)
...

Sheet 범주요약
A1: 대분류 | B1: 세부 구분 수 | C1: 선박 피처 수 | D1: Pool A 후보 | E1: Pool B 후보 | F1: Pool B 최종30
A2: 속도 구조(C) | B2: 7 | C2: =COUNTIF(선박피처!$C$2:$C$347,A2) | D2: =COUNTIFS(선박피처!$C$2:$C$347,A2,선박피처!$L$2:$L$347,"O") | E2: =COUNTIFS(선박피처!$C$2:$C$347,A2,선박피처!$M$2:$M$347,"O") | F2: =COUNTIFS(선박피처!$C$2:$C$347,A2,선박피처!$N$2:$N$347,"O")
A3: 방향·회전(D) | B3: 4 | C3: =COUNTIF(선박피처!$C$2:$C$347,A3) | D3: =COUNTIFS(선박피처!$C$2:$C$347,A3,선박피처!$L$2:$L$347,"O") | E3: =COUNTIFS(선박피처!$C$2:$C$347,A3,선박피처!$M$2:$M$347,"O") | F3: =COUNTIFS(선박피처!$C$2:$C$347,A3,선박피처!$N$2:$N$347,"O")
A4: 경로형태·직선투망(B) | B4: 3 | C4: =COUNTIF(선박피처!$C$2:$C$347,A4) | D4: =COUNTIFS(선박피처!$C$2:$C$347,A4,선박피처!$L$2:$L$347,"O") | E4: =COUNTIFS(선박피처!$C$2:$C$347,A4,선박피처!$M$2:$M$347,"O") | F4: =COUNTIFS(선박피처!$C$2:$C$347,A4,선박피처!$N$2:$N$347,"O")
A5: 이동량·공간범위 | B5: 6 | C5: =COUNTIF(선박피처!$C$2:$C$347,A5) | D5: =COUNTIFS(선박피처!$C$2:$C$347,A5,선박피처!$L$2:$L$347,"O") | E5: =COUNTIFS(선박피처!$C$2:$C$347,A5,선박피처!$M$2:$M$347,"O") | F5: =COUNTIFS(선박피처!$C$2:$C$347,A5,선박피처!$N$2:$N$347,"O")
A6: 시간 사용·항차 | B6: 4 | C6: =COUNTIF(선박피처!$C$2:$C$347,A6) | D6: =COUNTIFS(선박피처!$C$2:$C$347,A6,선박피처!$L$2:$L$347,"O") | E6: =COUNTIFS(선박피처!$C$2:$C$347,A6,선박피처!$M$2:$M$347,"O") | F6: =COUNTIFS(선박피처!$C$2:$C$347,A6,선박피처!$N$2:$N$347,"O")
A7: 하루 리듬·시각(E) | B7: 4 | C7: =COUNTIF(선박피처!$C$2:$C$347,A7) | D7: =COUNTIFS(선박피처!$C$2:$C$347,A7,선박피처!$L$2:$L$347,"O") | E7: =COUNTIFS(선박피처!$C$2:$C$347,A7,선박피처!$M$2:$M$347,"O") | F7: =COUNTIFS(선박피처!$C$2:$C$347,A7,선박피처!$N$2:$N$347,"O")
A8: 재방문·어장반복(A) | B8: 2 | C8: =COUNTIF(선박피처!$C$2:$C$347,A8) | D8: =COUNTIFS(선박피처!$C$2:$C$347,A8,선박피처!$L$2:$L$347,"O") | E8: =COUNTIFS(선박피처!$C$2:$C$347,A8,선박피처!$M$2:$M$347,"O") | F8: =COUNTIFS(선박피처!$C$2:$C$347,A8,선박피처!$N$2:$N$347,"O")
A9: 체류점 | B9: 1 | C9: =COUNTIF(선박피처!$C$2:$C$347,A9) | D9: =COUNTIFS(선박피처!$C$2:$C$347,A9,선박피처!$L$2:$L$347,"O") | E9: =COUNTIFS(선박피처!$C$2:$C$347,A9,선박피처!$M$2:$M$347,"O") | F9: =COUNTIFS(선박피처!$C$2:$C$347,A9,선박피처!$N$2:$N$347,"O")
A10: 품질·기록량 | B10: 3 | C10: =COUNTIF(선박피처!$C$2:$C$347,A10) | D10: =COUNTIFS(선박피처!$C$2:$C$347,A10,선박피처!$L$2:$L$347,"O") | E10: =COUNTIFS(선박피처!$C$2:$C$347,A10,선박피처!$M$2:$M$347,"O") | F10: =COUNTIFS(선박피처!$C$2:$C$347,A10,선박피처!$N$2:$N$347,"O")
A11: 일 유형·이질성(G) | B11: 1 | C11: =COUNTIF(선박피처!$C$2:$C$347,A11) | D11: =COUNTIFS(선박피처!$C$2:$C$347,A11,선박피처!$L$2:$L$347,"O") | E11: =COUNTIFS(선박피처!$C$2:$C$347,A11,선박피처!$M$2:$M$347,"O") | F11: =COUNTIFS(선박피처!$C$2:$C$347,A11,선박피처!$N$2:$N$347,"O")
A12: 계절(H) | B12: 1 | C12: =COUNTIF(선박피처!$C$2:$C$347,A12) | D12: =COUNTIFS(선박피처!$C$2:$C$347,A12,선박피처!$L$2:$L$347,"O") | E12: =COUNTIFS(선박피처!$C$2:$C$347,A12,선박피처!$M$2:$M$347,"O") | F12: =COUNTIFS(선박피처!$C$2:$C$347,A12,선박피처!$N$2:$N$347,"O")
A13: 위치(LOC) | B13: 1 | C13: =COUNTIF(선박피처!$C$2:$C$347,A13) | D13: =COUNTIFS(선박피처!$C$2:$C$347,A13,선박피처!$L$2:$L$347,"O") | E13: =COUNTIFS(선박피처!$C$2:$C$347,A13,선박피처!$M$2:$M$347,"O") | F13: =COUNTIFS(선박피처!$C$2:$C$347,A13,선박피처!$N$2:$N$347,"O")
A14: 합계 | B14: =SUM(B2:B13) | C14: =SUM(C2:C13) | D14: =SUM(D2:D13) | E14: =SUM(E2:E13) | F14: =SUM(F2:F13)
A16: ※ 숫자는 '선박피처' 시트를 COUNTIF 로 세는 수식 (선박피처를 수정하면 자동 갱신)

Sheet 범주구조
A1: 대분류 | B1: 세부 구분 | C1: 무엇을 재나 | D1: 출처 | E1: 기본 피처 (원천 값) | F1: 선박 피처 수 | G1: B 최종30 포함 | H1: 선박 피처 목록 | I1: B 최종30 포함 피처
A2: 속도 구조(C) | B2: 10분 구간 속도 | C2: 평활 경로 10분 간격 추정 속도(kn)의 통계 | D2: 나연, 진우 | E2: sp_mean, sp_std, sp_p50, sp_p90, sp_max, sp_change_mean | F2: =COUNTIFS(선박피처!$C$2:$C$347,A2,선박피처!$D$2:$D$347,B2) | G2: =COUNTIFS(선박피처!$C$2:$C$347,A2,선박피처!$D$2:$D$347,B2,선박피처!$N$2:$N$347,"O") | H2: mv_sp_mean_mean, mv_sp_p90_mean, mv_sp_std_mean, mv_sp_change_mean_mean, mv_sp_mean_median, mv_sp_p90_median, mv_sp_std_median, mv_sp_change_mean_median, mv_sp_mean_std, mv_sp_p90_std, mv_sp_std_std, mv_sp_change_mean_std, fh_sp_p50_q50, fh_sp_p90_q50, fh_sp_p50_q90, fh_sp_p90_q90
A3: 속도 구조(C) | B3: 속도 구간 비율 | C3: 정지/저속/중속/고속 구간이 차지하는 비율 | D3: 나연, 진우 | E3: frac_stop, frac_slow, frac_mid, frac_fast, frac_stop_mean | F3: =COUNTIFS(선박피처!$C$2:$C$347,A3,선박피처!$D$2:$D$347,B3) | G3: =COUNTIFS(선박피처!$C$2:$C$347,A3,선박피처!$D$2:$D$347,B3,선박피처!$N$2:$N$347,"O") | H3: mv_frac_slow_mean, mv_frac_mid_mean, mv_frac_fast_mean, mv_frac_slow_median, mv_frac_mid_median, mv_frac_fast_median, mv_frac_slow_std, mv_frac_mid_std, mv_frac_fast_std, fh_frac_slow_q50, fh_frac_mid_q50, fh_frac_slow_q90, fh_frac_mid_q90
A4: 속도 구조(C) | B4: 5-step 강건 속도 | C4: 5개 점 간격으로 잰 속도: GPS 지터에 덜 흔들림 (민성 검증) | D4: 민성 | E4: ks_speed_mean, ks_speed_med, ks_speed_p90, ks_frac_stat, ks_frac_drift, ks_frac_fish, ks_frac_transit | F4: =COUNTIFS(선박피처!$C$2:$C$347,A4,선박피처!$D$2:$D$347,B4) | G4: =COUNTIFS(선박피처!$C$2:$C$347,A4,선박피처!$D$2:$D$347,B4,선박피처!$N$2:$N$347,"O") | H4: mv_ks_speed_med_mean, mv_ks_speed_p90_mean, mv_ks_speed_med_median, mv_ks_speed_p90_median, mv_ks_speed_med_std, mv_ks_speed_p90_std, fh_ks_speed_med_q50, fh_ks_speed_p90_q50, fh_ks_speed_med_q90, fh_ks_speed_p90_q90
A5: 속도 구조(C) | B5: 저속 연속·속도 다양성 | C5: 양망 같은 긴 저속 구간, 여러 속도를 섞어 쓰는 정도 | D5: 가설 C | E5: slow_run_max_min, speed_entropy | F5: =COUNTIFS(선박피처!$C$2:$C$347,A5,선박피처!$D$2:$D$347,B5) | G5: =COUNTIFS(선박피처!$C$2:$C$347,A5,선박피처!$D$2:$D$347,B5,선박피처!$N$2:$N$347,"O") | H5: mv_slow_run_max_min_mean, mv_speed_entropy_mean, mv_slow_run_max_min_median, mv_speed_entropy_median, mv_slow_run_max_min_std, mv_speed_entropy_std, fh_slow_run_max_min_q50, fh_speed_entropy_q50, fh_slow_run_max_min_q90, fh_speed_entropy_q90
A6: 속도 구조(C) | B6: 점 간 step 크기 | C6: 연속 GPS 점 사이 거리의 크기와 변동 | D6: 민성, 지유, 진우 | E6: step_mean_m, step_med_m, step_std_m, step_max_m, step_max_raw_m, step_cv, movement_per_point | F6: =COUNTIFS(선박피처!$C$2:$C$347,A6,선박피처!$D$2:$D$347,B6) | G6: =COUNTIFS(선박피처!$C$2:$C$347,A6,선박피처!$D$2:$D$347,B6,선박피처!$N$2:$N$347,"O") | H6: mv_step_cv_mean, mv_step_cv_median, mv_step_cv_std
A7: 속도 구조(C) | B7: 이동 리듬(스펙트럼) | C7: step 길이 신호의 주파수 분석 (진우) | D7: 진우 | E7: spec_entropy, lowfreq_ratio | F7: =COUNTIFS(선박피처!$C$2:$C$347,A7,선박피처!$D$2:$D$347,B7) | G7: =COUNTIFS(선박피처!$C$2:$C$347,A7,선박피처!$D$2:$D$347,B7,선박피처!$N$2:$N$347,"O") | H7: mv_spec_entropy_mean, mv_lowfreq_ratio_mean, mv_spec_entropy_median, mv_lowfreq_ratio_median, mv_spec_entropy_std, mv_lowfreq_ratio_std
A8: 속도 구조(C) | B8: 시간대 간 점프 | C8: 앞 시간 끝점↔다음 시간 시작점 거리 | D8: 민성 | E8: inter_hour_jump_med_km | F8: =COUNTIFS(선박피처!$C$2:$C$347,A8,선박피처!$D$2:$D$347,B8) | G8: =COUNTIFS(선박피처!$C$2:$C$347,A8,선박피처!$D$2:$D$347,B8,선박피처!$N$2:$N$347,"O") | H8: inter_hour_jump_med_km_mean, inter_hour_jump_med_km_median, inter_hour_jump_med_km_std | I8: inter_hour_jump_med_km_median
A9: 방향·회전(D) | B9: 방향 일관성 | C9: 한 방향으로 가는지, 사방으로 흩어지는지 | D9: 나연, 민성, 지유, 진우 | E9: heading_R, bearing_std, ks_heading_R, drift_heading_R_q50 | F9: =COUNTIFS(선박피처!$C$2:$C$347,A9,선박피처!$D$2:$D$347,B9) | G9: =COUNTIFS(선박피처!$C$2:$C$347,A9,선박피처!$D$2:$D$347,B9,선박피처!$N$2:$N$347,"O") | H9: mv_heading_R_mean, mv_bearing_std_mean, mv_ks_heading_R_mean, mv_heading_R_median, mv_bearing_std_median, mv_ks_heading_R_median, mv_heading_R_std, mv_bearing_std_std, mv_ks_heading_R_std, fh_ks_heading_R_q50, fh_ks_heading_R_q90, drift_heading_R_q50
A10: 방향·회전(D) | B10: 회전각 | C10: 진행 방향이 꺾이는 각도 | D10: 공통, 민성, 지유 | E10: turn_mean, turn_std, turn_max, ks_turn_med | F10: =COUNTIFS(선박피처!$C$2:$C$347,A10,선박피처!$D$2:$D$347,B10) | G10: =COUNTIFS(선박피처!$C$2:$C$347,A10,선박피처!$D$2:$D$347,B10,선박피처!$N$2:$N$347,"O") | H10: mv_turn_mean_mean, mv_turn_std_mean, mv_ks_turn_med_mean, mv_turn_mean_median, mv_turn_std_median, mv_ks_turn_med_median, mv_turn_mean_std, mv_turn_std_std, mv_ks_turn_med_std, fh_ks_turn_med_q50, fh_turn_mean_q50, fh_ks_turn_med_q90, fh_turn_mean_q90 | I10: fh_turn_mean_q90
A11: 방향·회전(D) | B11: 급선회·U턴 | C11: 크게 꺾거나 되돌아가는 횟수/비율 | D11: 나연, 민성, 지유, 진우 | E11: n_turn45, n_turn90, n_uturn, large_turn_ratio, uturn_ratio, turn90_per_km | F11: =COUNTIFS(선박피처!$C$2:$C$347,A11,선박피처!$D$2:$D$347,B11) | G11: =COUNTIFS(선박피처!$C$2:$C$347,A11,선박피처!$D$2:$D$347,B11,선박피처!$N$2:$N$347,"O") | H11: mv_uturn_ratio_mean, mv_turn90_per_km_mean, mv_large_turn_ratio_mean, mv_uturn_ratio_median, mv_turn90_per_km_median, mv_large_turn_ratio_median, mv_uturn_ratio_std, mv_turn90_per_km_std, mv_large_turn_ratio_std
A12: 방향·회전(D) | B12: 루프 | C12: 누적 회전으로 센 제자리 맴돌기 (가설 D) | D12: 가설 D | E12: loops | F12: =COUNTIFS(선박피처!$C$2:$C$347,A12,선박피처!$D$2:$D$347,B12) | G12: =COUNTIFS(선박피처!$C$2:$C$347,A12,선박피처!$D$2:$D$347,B12,선박피처!$N$2:$N$347,"O") | H12: mv_loops_mean, mv_loops_median, mv_loops_std
A13: 경로형태·직선투망(B) | B13: 직진도·구불거림 | C13: 얼마나 곧게 가는가 | D13: 가설 B, 공통, 지유 | E13: straightness, day_straightness, seg_sinuosity_mean | F13: =COUNTIFS(선박피처!$C$2:$C$347,A13,선박피처!$D$2:$D$347,B13) | G13: =COUNTIFS(선박피처!$C$2:$C$347,A13,선박피처!$D$2:$D$347,B13,선박피처!$N$2:$N$347,"O") | H13: day_straightness_mean, mv_straightness_mean, mv_seg_sinuosity_mean_mean, day_straightness_median, mv_straightness_median, mv_seg_sinuosity_mean_median, day_straightness_std, mv_straightness_std, mv_seg_sinuosity_mean_std, fh_straightness_q50, fh_straightness_q90 | I13: mv_seg_sinuosity_mean_median
A14: 경로형태·직선투망(B) | B14: 경로 반복도 | C14: 좁은 범위 안을 얼마나 오가는가 | D14: 나연 | E14: path_over_diag, path_over_rg | F14: =COUNTIFS(선박피처!$C$2:$C$347,A14,선박피처!$D$2:$D$347,B14) | G14: =COUNTIFS(선박피처!$C$2:$C$347,A14,선박피처!$D$2:$D$347,B14,선박피처!$N$2:$N$347,"O") | H14: mv_path_over_rg_mean, mv_path_over_diag_mean, mv_path_over_rg_median, mv_path_over_diag_median, mv_path_over_rg_std, mv_path_over_diag_std, fh_path_over_rg_q50, fh_path_over_rg_q90
A15: 경로형태·직선투망(B) | B15: 직선 투망 형상 | C15: 그물을 직선으로 펼치는 투망 패턴 (가설 B) | D15: 가설 B, 나연, 민성 | E15: pca_elong, ks_straight_max_m, bbox_aspect | F15: =COUNTIFS(선박피처!$C$2:$C$347,A15,선박피처!$D$2:$D$347,B15) | G15: =COUNTIFS(선박피처!$C$2:$C$347,A15,선박피처!$D$2:$D$347,B15,선박피처!$N$2:$N$347,"O") | H15: mv_bbox_aspect_mean, mv_pca_elong_mean, mv_ks_straight_max_m_mean, mv_bbox_aspect_median, mv_pca_elong_median, mv_ks_straight_max_m_median, mv_bbox_aspect_std, mv_pca_elong_std, mv_ks_straight_max_m_std, fh_ks_straight_max_m_q50, fh_pca_elong_q50, fh_ks_straight_max_m_q90, fh_pca_elong_q90 | I15: mv_pca_elong_median, mv_ks_straight_max_m_std, fh_pca_elong_q50, fh_pca_elong_q90
A16: 이동량·공간범위 | B16: 이동거리 | C16: 얼마나 많이 움직였나 | D16: 나연, 지유, 진우 | E16: dist_m, dist_pts_m, dist_raw_m, dist_day_km, dist_raw_day_km | F16: =COUNTIFS(선박피처!$C$2:$C$347,A16,선박피처!$D$2:$D$347,B16) | G16: =COUNTIFS(선박피처!$C$2:$C$347,A16,선박피처!$D$2:$D$347,B16,선박피처!$N$2:$N$347,"O") | H16: dist_day_km_mean, dist_day_km_median, dist_day_km_std, dist_day_km_p90, fh_dist_m_q50, fh_dist_m_q90 | I16: dist_day_km_std
A17: 이동량·공간범위 | B17: 변위·이격 | C17: 출발점에서 얼마나 멀어졌나 | D17: 공통, 나연, 민성, 지유 | E17: net_disp_m, max_from_start_m, near_zero_disp, day_net_disp_km, day_range_q95_km | F17: =COUNTIFS(선박피처!$C$2:$C$347,A17,선박피처!$D$2:$D$347,B17) | G17: =COUNTIFS(선박피처!$C$2:$C$347,A17,선박피처!$D$2:$D$347,B17,선박피처!$N$2:$N$347,"O") | H17: day_net_disp_km_mean, day_range_q95_km_mean, day_net_disp_km_median, day_range_q95_km_median, day_net_disp_km_std, day_range_q95_km_std, day_range_q95_km_p90
A18: 이동량·공간범위 | B18: 활동 범위(1시간) | C18: 1시간 동안 쓴 공간의 크기 | D18: 나연, 민성, 지유, 진우 | E18: bbox_w_m, bbox_h_m, bbox_diag_m, bbox_area_km2, rg_m, rg_med_m, max_radius_m, hull_area_m2, smooth_diag_m | F18: =COUNTIFS(선박피처!$C$2:$C$347,A18,선박피처!$D$2:$D$347,B18) | G18: =COUNTIFS(선박피처!$C$2:$C$347,A18,선박피처!$D$2:$D$347,B18,선박피처!$N$2:$N$347,"O") | H18: mv_rg_m_mean, mv_rg_med_m_mean, mv_bbox_diag_m_mean, mv_hull_area_m2_mean, mv_rg_m_median, mv_rg_med_m_median, mv_bbox_diag_m_median, mv_hull_area_m2_median, mv_rg_m_std, mv_rg_med_m_std, mv_bbox_diag_m_std, mv_hull_area_m2_std, fh_rg_med_m_q50, fh_rg_med_m_q90
A19: 이동량·공간범위 | B19: 활동 범위(하루) | C19: 하루 동안 시간대 중심들이 퍼진 크기 | D19: 나연 | E19: day_rg_km, day_bbox_diag_km | F19: =COUNTIFS(선박피처!$C$2:$C$347,A19,선박피처!$D$2:$D$347,B19) | G19: =COUNTIFS(선박피처!$C$2:$C$347,A19,선박피처!$D$2:$D$347,B19,선박피처!$N$2:$N$347,"O") | H19: day_rg_km_mean, day_bbox_diag_km_mean, day_rg_km_median, day_bbox_diag_km_median, day_rg_km_std, day_bbox_diag_km_std
A20: 이동량·공간범위 | B20: 조업 해역 크기(선박) | C20: 6개월간 조업 해역의 넓이·퍼짐 (위치 아님, 크기) | D20: 나연, 민성 | E20: area_range_km, fishing_area_radius | F20: =COUNTIFS(선박피처!$C$2:$C$347,A20,선박피처!$D$2:$D$347,B20) | G20: =COUNTIFS(선박피처!$C$2:$C$347,A20,선박피처!$D$2:$D$347,B20,선박피처!$N$2:$N$347,"O") | H20: area_range_km, fishing_area_radius | I20: area_range_km
A21: 이동량·공간범위 | B21: 모항·항구 거리 | C21: 모항/항구에서 얼마나 멀리 나가나 | D21: 나연, 민성 | E21: home_km_max, home_km_mean, home_km_start, home_km_end, port_km_mean, trip_max_dist_q50 | F21: =COUNTIFS(선박피처!$C$2:$C$347,A21,선박피처!$D$2:$D$347,B21) | G21: =COUNTIFS(선박피처!$C$2:$C$347,A21,선박피처!$D$2:$D$347,B21,선박피처!$N$2:$N$347,"O") | H21: home_km_max_mean, home_km_mean_mean, home_km_max_median, home_km_mean_median, home_km_max_std, home_km_mean_std, home_km_max_p90, trip_max_dist_q50 | I21: home_km_max_mean
A22: 시간 사용·항차 | B22: 상태별 시간 비율 | C22: 항구 정박/해상 정지/표류/조업속도/항해에 쓴 시간 비율 (민성 A) | D22: 나연, 민성, 민성(H4), 지유 | E22: port_share, sea_stationary_share, sea_stationary_share_sea, drift_share, drift_share_sea, fishing_speed_share, fishing_speed_share_sea, transit_share, transit_share_sea, sea_stop_share, fish_share, in_port_ratio, stationary_ratio, moving_hour_share, is_stationary | F22: =COUNTIFS(선박피처!$C$2:$C$347,A22,선박피처!$D$2:$D$347,B22) | G22: =COUNTIFS(선박피처!$C$2:$C$347,A22,선박피처!$D$2:$D$347,B22,선박피처!$N$2:$N$347,"O") | H22: port_share, sea_stationary_share, sea_stationary_share_sea, drift_share, drift_share_sea, fishing_speed_share, fishing_speed_share_sea, transit_share, transit_share_sea, moving_hour_share, in_port_ratio_mean, sea_stop_share_mean, drift_share_mean, fish_share_mean, transit_share_mean, stationary_ratio_mean, in_port_ratio_median, sea_stop_share_median, drift_share_median, fish_share_median, transit_share_median, stationary_ratio_median, in_port_ratio_std, sea_stop_share_std, drift_share_std, fish_share_std, transit_share_std, stationary_ratio_std
A23: 시간 사용·항차 | B23: 상태 전환 | C23: 상태가 얼마나 자주 바뀌나 | D23: 나연, 민성 | E23: n_transitions, transitions_per_day, n_stop_move_switch | F23: =COUNTIFS(선박피처!$C$2:$C$347,A23,선박피처!$D$2:$D$347,B23) | G23: =COUNTIFS(선박피처!$C$2:$C$347,A23,선박피처!$D$2:$D$347,B23,선박피처!$N$2:$N$347,"O") | H23: transitions_per_day, n_transitions_mean, mv_n_stop_move_switch_mean, n_transitions_median, mv_n_stop_move_switch_median, n_transitions_std, mv_n_stop_move_switch_std | I23: mv_n_stop_move_switch_median
A24: 시간 사용·항차 | B24: 항차(출항~귀항) | C24: 출항 횟수, 항차 길이, 귀항 여부 (민성 B) | D24: 나연, 민성 | E24: departures, trips_per_day, trip_hours_q50, returned_ratio, returned_to_port | F24: =COUNTIFS(선박피처!$C$2:$C$347,A24,선박피처!$D$2:$D$347,B24) | G24: =COUNTIFS(선박피처!$C$2:$C$347,A24,선박피처!$D$2:$D$347,B24,선박피처!$N$2:$N$347,"O") | H24: returned_ratio, trips_per_day, departures_mean, departures_median, departures_std, trip_hours_q50
A25: 시간 사용·항차 | B25: 출어 활동량 | C25: 얼마나 자주·오래 바다에 나가나 | D25: 나연, 민성 | E25: n_days, n_months, n_moving_days, moving_days_ratio, moving_days_per_month, hours_per_day, n_hours, n_moving_hours, moving_ratio | F25: =COUNTIFS(선박피처!$C$2:$C$347,A25,선박피처!$D$2:$D$347,B25) | G25: =COUNTIFS(선박피처!$C$2:$C$347,A25,선박피처!$D$2:$D$347,B25,선박피처!$N$2:$N$347,"O") | H25: n_days, n_months, n_moving_days, moving_days_ratio, moving_days_per_month, hours_per_day, n_hours_mean, n_moving_hours_mean, moving_ratio_mean, n_hours_median, n_moving_hours_median, moving_ratio_median, n_hours_std, n_moving_hours_std, moving_ratio_std, n_moving_hours_p90 | I25: moving_days_per_month
A26: 하루 리듬·시각(E) | B26: 시작·종료 시각 | C26: 몇 시에 나가고 몇 시에 끝내나 | D26: 나연, 민성, 지유 | E26: first_hour, last_hour, mv_first_hour, mv_last_hour, departure_hour_q50 | F26: =COUNTIFS(선박피처!$C$2:$C$347,A26,선박피처!$D$2:$D$347,B26) | G26: =COUNTIFS(선박피처!$C$2:$C$347,A26,선박피처!$D$2:$D$347,B26,선박피처!$N$2:$N$347,"O") | H26: first_hour_mean, last_hour_mean, mv_first_hour_mean, mv_last_hour_mean, first_hour_median, last_hour_median, mv_first_hour_median, mv_last_hour_median, first_hour_std, last_hour_std, mv_first_hour_std, mv_last_hour_std, departure_hour_q50 | I26: mv_last_hour_mean, mv_last_hour_std
A27: 하루 리듬·시각(E) | B27: 조업 시간 폭 | C27: 하루 중 활동한 시간의 길이 | D27: 나연, 민성 | E27: active_span_h, mv_span_h | F27: =COUNTIFS(선박피처!$C$2:$C$347,A27,선박피처!$D$2:$D$347,B27) | G27: =COUNTIFS(선박피처!$C$2:$C$347,A27,선박피처!$D$2:$D$347,B27,선박피처!$N$2:$N$347,"O") | H27: active_span_h_mean, mv_span_h_mean, active_span_h_median, mv_span_h_median, active_span_h_std, mv_span_h_std
A28: 하루 리듬·시각(E) | B28: 시간대 비중 | C28: 새벽/오전/오후/밤 중 언제 조업하나 | D28: 나연, 민성, 지유 | E28: mv_share_dawn, mv_share_morning, mv_share_afternoon, mv_share_night, night_ratio, fishing_night_share | F28: =COUNTIFS(선박피처!$C$2:$C$347,A28,선박피처!$D$2:$D$347,B28) | G28: =COUNTIFS(선박피처!$C$2:$C$347,A28,선박피처!$D$2:$D$347,B28,선박피처!$N$2:$N$347,"O") | H28: mv_share_dawn_mean, mv_share_morning_mean, mv_share_afternoon_mean, mv_share_night_mean, night_ratio_mean, mv_share_dawn_median, mv_share_morning_median, mv_share_afternoon_median, mv_share_night_median, night_ratio_median, mv_share_dawn_std, mv_share_morning_std, mv_share_afternoon_std, mv_share_night_std, night_ratio_std, fishing_night_share | I28: mv_share_night_mean, fishing_night_share
A29: 하루 리듬·시각(E) | B29: 이동 블록 구조 | C29: 투망-휴식-양망처럼 하루가 몇 덩어리로 나뉘나 (가설 E) | D29: 가설 E, 민성 | E29: active_block_count, longest_streak, max_block_gap_h | F29: =COUNTIFS(선박피처!$C$2:$C$347,A29,선박피처!$D$2:$D$347,B29) | G29: =COUNTIFS(선박피처!$C$2:$C$347,A29,선박피처!$D$2:$D$347,B29,선박피처!$N$2:$N$347,"O") | H29: longest_streak_mean, active_block_count_mean, max_block_gap_h_mean, longest_streak_median, active_block_count_median, max_block_gap_h_median, longest_streak_std, active_block_count_std, max_block_gap_h_std | I29: longest_streak_mean, longest_streak_std
A30: 재방문·어장반복(A) | B30: 하루 내 재방문 | C30: 같은 200m 칸을 떠났다가 다시 오나 (어구 회수, 가설 A) | D30: 가설 A | E30: return_after_absence, revisit_cell_ratio, n_cells_200m, top3_cell_share | F30: =COUNTIFS(선박피처!$C$2:$C$347,A30,선박피처!$D$2:$D$347,B30) | G30: =COUNTIFS(선박피처!$C$2:$C$347,A30,선박피처!$D$2:$D$347,B30,선박피처!$N$2:$N$347,"O") | H30: return_after_absence_mean, revisit_cell_ratio_mean, top3_cell_share_mean, n_cells_200m_mean, return_after_absence_median, revisit_cell_ratio_median, top3_cell_share_median, n_cells_200m_median, return_after_absence_std, revisit_cell_ratio_std, top3_cell_share_std, n_cells_200m_std | I30: revisit_cell_ratio_mean, top3_cell_share_median, revisit_cell_ratio_std, n_cells_200m_std
A31: 재방문·어장반복(A) | B31: 날짜 간 어장 반복 | C31: 여러 날 같은 어장을 다시 찾나 | D31: 가설 A, 민성 | E31: cross_day_revisit, site_jaccard_mean | F31: =COUNTIFS(선박피처!$C$2:$C$347,A31,선박피처!$D$2:$D$347,B31) | G31: =COUNTIFS(선박피처!$C$2:$C$347,A31,선박피처!$D$2:$D$347,B31,선박피처!$N$2:$N$347,"O") | H31: cross_day_revisit, site_jaccard_mean | I31: cross_day_revisit
A32: 체류점 | B32: 체류점 | C32: 반경 30m 안에 3점 이상 머문 지점 (민성, 지터 강건 정지 판정) | D32: 민성 | E32: n_stays, stay_frac | F32: =COUNTIFS(선박피처!$C$2:$C$347,A32,선박피처!$D$2:$D$347,B32) | G32: =COUNTIFS(선박피처!$C$2:$C$347,A32,선박피처!$D$2:$D$347,B32,선박피처!$N$2:$N$347,"O") | H32: mv_n_stays_mean, mv_stay_frac_mean, mv_n_stays_median, mv_stay_frac_median, mv_n_stays_std, mv_stay_frac_std, fh_n_stays_q50, fh_stay_frac_q50, fh_n_stays_q90, fh_stay_frac_q90 | I32: fh_n_stays_q90
A33: 품질·기록량 | B33: 기록량 | C33: GPS 점·구간이 얼마나 찍혔나 | D33: 나연, 지유, 진우 | E33: n_points_raw, n_points, n_segments, gap_count, pts_per_seg, uniq_pos_ratio, n_points_day, n_segments_mean, n_move_steps | F33: =COUNTIFS(선박피처!$C$2:$C$347,A33,선박피처!$D$2:$D$347,B33) | G33: =COUNTIFS(선박피처!$C$2:$C$347,A33,선박피처!$D$2:$D$347,B33,선박피처!$N$2:$N$347,"O") | H33: n_segments_mean_mean, mv_uniq_pos_ratio_mean, mv_n_segments_mean, mv_n_points_mean, n_segments_mean_median, mv_uniq_pos_ratio_median, mv_n_segments_median, mv_n_points_median, n_segments_mean_std, mv_uniq_pos_ratio_std, mv_n_segments_std, mv_n_points_std, fh_uniq_pos_ratio_q50, fh_uniq_pos_ratio_q90
A34: 품질·기록량 | B34: GPS 튐·정제 | C34: 튐·점프로 제거된 양과 정제 전후 차이 (구성 C안 품질 피처) | D34: 나연, 지유 | E34: n_spikes, spike_ratio, n_jumps, n_bin_spikes, n_bin_jumps, bin_dispersion_m, raw_clean_diff_m, raw_clean_ratio, overspeed_flag, jump_share_day, n_jumps_day | F34: =COUNTIFS(선박피처!$C$2:$C$347,A34,선박피처!$D$2:$D$347,B34) | G34: =COUNTIFS(선박피처!$C$2:$C$347,A34,선박피처!$D$2:$D$347,B34,선박피처!$N$2:$N$347,"O") | H34: jump_share_day_mean, mv_spike_ratio_mean, mv_raw_clean_ratio_mean, mv_bin_dispersion_m_mean, jump_share_day_median, mv_spike_ratio_median, mv_raw_clean_ratio_median, mv_bin_dispersion_m_median, jump_share_day_std, mv_spike_ratio_std, mv_raw_clean_ratio_std, mv_bin_dispersion_m_std
A35: 품질·기록량 | B35: 신호 끊김 | C35: 구간 사이 끊긴 거리 | D35: 지유, 진우 | E35: gap_dist_m, max_gap_m | F35: =COUNTIFS(선박피처!$C$2:$C$347,A35,선박피처!$D$2:$D$347,B35) | G35: =COUNTIFS(선박피처!$C$2:$C$347,A35,선박피처!$D$2:$D$347,B35,선박피처!$N$2:$N$347,"O")
A36: 일 유형·이질성(G) | B36: 출어일 유형 | C36: 하루 패턴 군집 비율과 다양성 (bag-of-days) | D36: 가설 G | E36: daytype_0_share, daytype_1_share, daytype_2_share, daytype_3_share, daytype_4_share, daytype_5_share, daytype_6_share, daytype_7_share, day_type_entropy | F36: =COUNTIFS(선박피처!$C$2:$C$347,A36,선박피처!$D$2:$D$347,B36) | G36: =COUNTIFS(선박피처!$C$2:$C$347,A36,선박피처!$D$2:$D$347,B36,선박피처!$N$2:$N$347,"O") | H36: daytype_0_share, daytype_1_share, daytype_2_share, daytype_3_share, daytype_4_share, daytype_5_share, daytype_6_share, daytype_7_share, day_type_entropy | I36: daytype_2_share
A37: 계절(H) | B37: 월별 출어 | C37: 어느 달에 주로 나가나 | D37: 가설 H, 민성 | E37: season_m1_share, season_m2_share, season_m3_share, season_m4_share, season_m5_share, season_m6_share, month | F37: =COUNTIFS(선박피처!$C$2:$C$347,A37,선박피처!$D$2:$D$347,B37) | G37: =COUNTIFS(선박피처!$C$2:$C$347,A37,선박피처!$D$2:$D$347,B37,선박피처!$N$2:$N$347,"O") | H37: season_m1_share, season_m2_share, season_m3_share, season_m4_share, season_m5_share, season_m6_share | I37: season_m3_share
A38: 위치(LOC) | B38: 좌표 | C38: 어디서 활동하나 (shortcut 위험 → Pool A 제외) | D38: 공통, 나연, 민성, 진우 | E38: lon_c, lat_c, lon_s, lat_s, lon_e, lat_e, lon_start, lat_start, lon_end, lat_end, mv_lon_c, mv_lat_c, home_lon, home_lat, fishing_lon, fishing_lat, home_port_km | F38: =COUNTIFS(선박피처!$C$2:$C$347,A38,선박피처!$D$2:$D$347,B38) | G38: =COUNTIFS(선박피처!$C$2:$C$347,A38,선박피처!$D$2:$D$347,B38,선박피처!$N$2:$N$347,"O") | H38: lon_c, lat_c, home_lon, home_lat, fishing_lon, fishing_lat, home_port_km | I38: lon_c, lat_c, home_lon, home_port_km

Sheet 선박피처
A1: No | B1: 피처명 | C1: 대분류 | D1: 세부 구분 | E1: 기본 피처 | F1: 기본 피처 설명 | G1: 만드는 방법 | H1: 계산 단위 | I1: 출처 | J1: 위치(LOC) | K1: 가설 | L1: Pool A 후보 | M1: Pool B 후보 | N1: Pool B 최종30 | O1: A 선정빈도 | P1: B 선정빈도 | Q1: A 순위 | R1: B 순위 | S1: 중복 시 대표(B)
A2: 1 | B2: n_days | C2: 시간 사용·항차 | D2: 출어 활동량 | E2: n_days | F2: 기록일 수 | G2: 선박 전체 기간에서 직접 계산 | H2: L3 선박 | I2: 나연 | L2: O | M2: O | O2: 1 | P2: 0 | Q2: 121 | R2: 95 | S2: n_moving_days
A3: 2 | B3: n_months | C3: 시간 사용·항차 | D3: 출어 활동량 | E3: n_months | F3: 기록 개월 수 | G3: 선박 전체 기간에서 직접 계산 | H3: L3 선박 | I3: 나연 | L3: O | M3: O | O3: 1 | P3: 0 | Q3: 158 | R3: 278
A4: 3 | B4: n_moving_days | C4: 시간 사용·항차 | D4: 출어 활동량 | E4: n_moving_days | F4: 출어일 수 | G4: 선박 전체 기간에서 직접 계산 | H4: L3 선박 | I4: 나연 | L4: O | M4: O | O4: 0 | P4: 0.2 | Q4: 313 | R4: 42 | S4: moving_days_per_month
A5: 4 | B5: moving_days_ratio | C5: 시간 사용·항차 | D5: 출어 활동량 | E5: moving_days_ratio | F5: 출어일 비율 | G5: 선박 전체 기간에서 직접 계산 | H5: L3 선박 | I5: 나연 | L5: O | M5: O | O5: 1 | P5: 0 | Q5: 109 | R5: 271
A6: 5 | B6: moving_days_per_month | C6: 시간 사용·항차 | D6: 출어 활동량 | E6: moving_days_per_month | F6: 월평균 출어일 | G6: 선박 전체 기간에서 직접 계산 | H6: L3 선박 | I6: 나연 | L6: O | M6: O | N6: O | O6: 1 | P6: 0.6 | Q6: 9 | R6: 21 | S6: n_moving_days
A7: 6 | B7: hours_per_day | C7: 시간 사용·항차 | D7: 출어 활동량 | E7: hours_per_day | F7: 하루 평균 기록 시간 | G7: 선박 전체 기간에서 직접 계산 | H7: L3 선박 | I7: 나연 | L7: O | M7: O | O7: 1 | P7: 0 | Q7: 159 | R7: 212
A8: 7 | B8: port_share | C8: 시간 사용·항차 | D8: 상태별 시간 비율 | E8: port_share | F8: 항구 정박 시간 비율 | G8: 선박 전체 기간에서 직접 계산 | H8: L3 선박 | I8: 민성 | L8: O | M8: O | O8: 1 | P8: 0 | Q8: 177 | R8: 299
A9: 8 | B9: sea_stationary_share | C9: 시간 사용·항차 | D9: 상태별 시간 비율 | E9: sea_stationary_share | F9: 해상 정지 시간 비율 | G9: 선박 전체 기간에서 직접 계산 | H9: L3 선박 | I9: 민성 | K9: 가설 관련 | L9: O | M9: O | O9: 1 | P9: 0 | Q9: 182 | R9: 313
A10: 9 | B10: sea_stationary_share_sea | C10: 시간 사용·항차 | D10: 상태별 시간 비율 | E10: sea_stationary_share_sea | F10: 항구 제외 시간 중 해상 정지 비율 | G10: 선박 전체 기간에서 직접 계산 | H10: L3 선박 | I10: 민성(H4) | K10: 가설 관련 | L10: O | M10: O | O10: 1 | P10: 0 | Q10: 119 | R10: 127
A11: 10 | B11: drift_share | C11: 시간 사용·항차 | D11: 상태별 시간 비율 | E11: drift_share | F11: 표류(0.3~2kn) 시간 비율 (전체 기간) | G11: 선박 전체 기간에서 직접 계산 | H11: L3 선박 | I11: 민성 | K11: 가설 관련 | L11: O | M11: O | O11: 1 | P11: 0 | Q11: 103 | R11: 124
A12: 11 | B12: drift_share_sea | C12: 시간 사용·항차 | D12: 상태별 시간 비율 | E12: drift_share_sea | F12: 항구 제외 시간 중 표류 비율 | G12: 선박 전체 기간에서 직접 계산 | H12: L3 선박 | I12: 민성(H4) | K12: 가설 관련 | L12: O | M12: O | O12: 1 | P12: 0 | Q12: 163 | R12: 176
A13: 12 | B13: fishing_speed_share | C13: 시간 사용·항차 | D13: 상태별 시간 비율 | E13: fishing_speed_share | F13: 조업속도 시간 비율 | G13: 선박 전체 기간에서 직접 계산 | H13: L3 선박 | I13: 민성 | L13: O | M13: O | O13: 1 | P13: 0 | Q13: 188 | R13: 325
A14: 13 | B14: fishing_speed_share_sea | C14: 시간 사용·항차 | D14: 상태별 시간 비율 | E14: fishing_speed_share_sea | F14: 항구 제외 시간 중 조업속도 비율 | G14: 선박 전체 기간에서 직접 계산 | H14: L3 선박 | I14: 민성(H4) | L14: O | M14: O | O14: 1 | P14: 0 | Q14: 96 | R14: 122
A15: 14 | B15: transit_share | C15: 시간 사용·항차 | D15: 상태별 시간 비율 | E15: transit_share | F15: 항해(>5kn, 직선) 시간 비율 (전체 기간) | G15: 선박 전체 기간에서 직접 계산 | H15: L3 선박 | I15: 민성 | L15: O | M15: O | O15: 0.2 | P15: 0 | Q15: 306 | R15: 296 | S15: transit_share_sea
A16: 15 | B16: transit_share_sea | C16: 시간 사용·항차 | D16: 상태별 시간 비율 | E16: transit_share_sea | F16: 항구 제외 시간 중 항해 비율 | G16: 선박 전체 기간에서 직접 계산 | H16: L3 선박 | I16: 민성(H4) | L16: O | M16: O | O16: 0.4 | P16: 0 | Q16: 266 | R16: 298 | S16: transit_share
A17: 16 | B17: moving_hour_share | C17: 시간 사용·항차 | D17: 상태별 시간 비율 | E17: moving_hour_share | F17: 전체 시간 중 이동 시간 비율 | G17: 선박 전체 기간에서 직접 계산 | H17: L3 선박 | I17: 나연 | L17: O | M17: O | O17: 1 | P17: 0 | Q17: 153 | R17: 242
A18: 17 | B18: returned_ratio | C18: 시간 사용·항차 | D18: 항차(출항~귀항) | E18: returned_ratio | F18: 출어일 귀항 비율 | G18: 선박 전체 기간에서 직접 계산 | H18: L3 선박 | I18: 나연 | L18: O | M18: O | O18: 1 | P18: 0 | Q18: 43 | R18: 82
A19: 18 | B19: transitions_per_day | C19: 시간 사용·항차 | D19: 상태 전환 | E19: transitions_per_day | F19: 하루 평균 상태 전환 | G19: 선박 전체 기간에서 직접 계산 | H19: L3 선박 | I19: 민성 | L19: O | M19: O | O19: 0.8 | P19: 0 | Q19: 212 | R19: 129
A20: 19 | B20: trips_per_day | C20: 시간 사용·항차 | D20: 항차(출항~귀항) | E20: trips_per_day | F20: 하루 평균 출항 수 | G20: 선박 전체 기간에서 직접 계산 | H20: L3 선박 | I20: 민성 | L20: O | M20: O | O20: 0.8 | P20: 0 | Q20: 202 | R20: 141
A21: 20 | B21: n_hours_mean | C21: 시간 사용·항차 | D21: 출어 활동량 | E21: n_hours | F21: 하루 기록 시간대 수 | G21: 출어일 값들의 평균 | H21: L2→L3 | I21: 나연·민성 | L21: O | M21: O | O21: 0.6 | P21: 0 | Q21: 243 | R21: 268 | S21: active_span_h_mean
A22: 21 | B22: n_moving_hours_mean | C22: 시간 사용·항차 | D22: 출어 활동량 | E22: n_moving_hours | F22: 이동 시간대 수 | G22: 출어일 값들의 평균 | H22: L2→L3 | I22: 나연 | L22: O | M22: O | O22: 0.2 | P22: 0 | Q22: 291 | R22: 218 | S22: n_moving_hours_p90
A23: 22 | B23: moving_ratio_mean | C23: 시간 사용·항차 | D23: 출어 활동량 | E23: moving_ratio | F23: 이동 시간대 비율 | G23: 출어일 값들의 평균 | H23: L2→L3 | I23: 나연 | L23: O | M23: O | O23: 0.2 | P23: 0 | Q23: 289 | R23: 265 | S23: moving_ratio_median
A24: 23 | B24: active_span_h_mean | C24: 하루 리듬·시각(E) | D24: 조업 시간 폭 | E24: active_span_h | F24: 첫~마지막 기록 시간 폭 | G24: 출어일 값들의 평균 | H24: L2→L3 | I24: 나연 | L24: O | M24: O | O24: 0.4 | P24: 0 | Q24: 265 | R24: 111 | S24: active_span_h_median
A25: 24 | B25: first_hour_mean | C25: 하루 리듬·시각(E) | D25: 시작·종료 시각 | E25: first_hour | F25: 첫 기록 시각 | G25: 출어일 값들의 평균 | H25: L2→L3 | I25: 민성·지유 | L25: O | M25: O | O25: 1 | P25: 0.4 | Q25: 40 | R25: 36
A26: 25 | B26: last_hour_mean | C26: 하루 리듬·시각(E) | D26: 시작·종료 시각 | E26: last_hour | F26: 마지막 기록 시각 | G26: 출어일 값들의 평균 | H26: L2→L3 | I26: 민성·지유 | L26: O | M26: O | O26: 0.8 | P26: 0 | Q26: 194 | R26: 98 | S26: last_hour_median
A27: 26 | B27: dist_day_km_mean | C27: 이동량·공간범위 | D27: 이동거리 | E27: dist_day_km | F27: 하루 평활 이동거리(km) | G27: 출어일 값들의 평균 | H27: L2→L3 | I27: 나연·지유 | L27: O | M27: O | O27: 0.2 | P27: 0 | Q27: 286 | R27: 219 | S27: day_bbox_diag_km_mean
A28: 27 | B28: jump_share_day_mean | C28: 품질·기록량 | D28: GPS 튐·정제 | E28: jump_share_day | F28: 튐 비중 = 1 − 평활/원거리 | G28: 출어일 값들의 평균 | H28: L2→L3 | I28: 나연 | L28: O | M28: O | O28: 0.2 | P28: 0 | Q28: 310 | R28: 335 | S28: jump_share_day_median
A29: 28 | B29: day_net_disp_km_mean | C29: 이동량·공간범위 | D29: 변위·이격 | E29: day_net_disp_km | F29: 하루 시작→끝 변위(km) | G29: 출어일 값들의 평균 | H29: L2→L3 | I29: 나연 | L29: O | M29: O | O29: 1 | P29: 0.4 | Q29: 11 | R29: 35
A30: 29 | B30: day_straightness_mean | C30: 경로형태·직선투망(B) | D30: 직진도·구불거림 | E30: day_straightness | F30: 하루 직진도 = 변위/거리 | G30: 출어일 값들의 평균 | H30: L2→L3 | I30: 가설 B | L30: O | M30: O | O30: 1 | P30: 0 | Q30: 132 | R30: 214
A31: 30 | B31: day_rg_km_mean | C31: 이동량·공간범위 | D31: 활동 범위(하루) | E31: day_rg_km | F31: 시간대 중심들의 퍼짐(km) | G31: 출어일 값들의 평균 | H31: L2→L3 | I31: 나연 | L31: O | M31: O | O31: 0 | P31: 0.2 | Q31: 314 | R31: 49 | S31: home_km_max_mean
A32: 31 | B32: day_bbox_diag_km_mean | C32: 이동량·공간범위 | D32: 활동 범위(하루) | E32: day_bbox_diag_km | F32: 하루 활동범위 대각선(km) | G32: 출어일 값들의 평균 | H32: L2→L3 | I32: 나연 | L32: O | M32: O | O32: 0.2 | P32: 0.2 | Q32: 273 | R32: 48 | S32: home_km_max_mean
A33: 32 | B33: day_range_q95_km_mean | C33: 이동량·공간범위 | D33: 변위·이격 | E33: day_range_q95_km | F33: 첫 위치에서 95% 분위 이격(km, 지터 강건 day_range) | G33: 출어일 값들의 평균 | H33: L2→L3 | I33: 민성 | L33: O | M33: O | O33: 0 | P33: 0 | Q33: 312 | R33: 86 | S33: home_km_max_mean
A34: 33 | B34: home_km_max_mean | C34: 이동량·공간범위 | D34: 모항·항구 거리 | E34: home_km_max | F34: 모항에서 최대 거리(km) | G34: 출어일 값들의 평균 | H34: L2→L3 | I34: 민성·나연 | L34: O | M34: O | N34: O | O34: 0.4 | P34: 0.4 | Q34: 253 | R34: 24 | S34: day_bbox_diag_km_mean
A35: 34 | B35: home_km_mean_mean | C35: 이동량·공간범위 | D35: 모항·항구 거리 | E35: home_km_mean | F35: 모항에서 평균 거리(km) | G35: 출어일 값들의 평균 | H35: L2→L3 | I35: 나연 | L35: O | M35: O | O35: 0.6 | P35: 0.2 | Q35: 227 | R35: 50 | S35: home_km_mean_median
A36: 35 | B36: in_port_ratio_mean | C36: 시간 사용·항차 | D36: 상태별 시간 비율 | E36: in_port_ratio | F36: 항구 정박 시간 비율 | G36: 출어일 값들의 평균 | H36: L2→L3 | I36: 나연·민성 | L36: O | M36: O | O36: 1 | P36: 0 | Q36: 170 | R36: 251 | S36: in_port_ratio_median
A37: 36 | B37: sea_stop_share_mean | C37: 시간 사용·항차 | D37: 상태별 시간 비율 | E37: sea_stop_share | F37: 해상 정지 시간 비율 | G37: 출어일 값들의 평균 | H37: L2→L3 | I37: 민성 | L37: O | M37: O | O37: 1 | P37: 0.2 | Q37: 59 | R37: 51
A38: 37 | B38: drift_share_mean | C38: 시간 사용·항차 | D38: 상태별 시간 비율 | E38: drift_share | F38: 표류(0.3~2kn) 시간 비율 (전체 기간) | G38: 출어일 값들의 평균 | H38: L2→L3 | I38: 민성 | K38: 가설 관련 | L38: O | M38: O | O38: 1 | P38: 0 | Q38: 89 | R38: 199
A39: 38 | B39: fish_share_mean | C39: 시간 사용·항차 | D39: 상태별 시간 비율 | E39: fish_share | F39: 조업속도(2~5kn) 시간 비율 | G39: 출어일 값들의 평균 | H39: L2→L3 | I39: 민성 | L39: O | M39: O | O39: 1 | P39: 0 | Q39: 164 | R39: 316
A40: 39 | B40: transit_share_mean | C40: 시간 사용·항차 | D40: 상태별 시간 비율 | E40: transit_share | F40: 항해(>5kn, 직선) 시간 비율 (전체 기간) | G40: 출어일 값들의 평균 | H40: L2→L3 | I40: 민성 | L40: O | M40: O | O40: 0.4 | P40: 0 | Q40: 269 | R40: 287 | S40: transit_share
...

Sheet PoolB_최종30
A1: B 순위 | B1: 피처명 | C1: 대분류 | D1: 세부 구분 | E1: 한 줄 설명 | F1: 출처 | G1: 위치(LOC) | H1: 가설 | I1: 5fold 선정빈도
A2: 1 | B2: area_range_km | C2: 이동량·공간범위 | D2: 조업 해역 크기(선박) | E2: 조업 해역 넓이 (일별 중심 5~95% 범위, km) ← 선박 전체 기간에서 직접 계산 | F2: 나연 | I2: 1
A3: 2 | B3: cross_day_revisit | C3: 재방문·어장반복(A) | D3: 날짜 간 어장 반복 | E3: 조업 1km 격자 중 여러 날 다시 찾은 칸 비율 ← 선박 전체 기간에서 직접 계산 | F3: 민성·가설 A | H3: 가설 A(재방문) | I3: 1
A4: 3 | B4: mv_n_stop_move_switch_median | C4: 시간 사용·항차 | D4: 상태 전환 | E4: 정지↔이동 전환 횟수 ← 출어일마다 이동 시간대 평균 → 출어일들의 중앙값 | F4: 나연 | I4: 1
A5: 4 | B5: lat_c | C5: 위치(LOC) | D5: 좌표 | E5: 선박 대표 위도 (전체 시간 중앙값) ← 선박 전체 기간에서 직접 계산 | F5: 공통 | G5: O | I5: 0.8
A6: 5 | B6: longest_streak_std | C6: 하루 리듬·시각(E) | D6: 이동 블록 구조 | E6: 최장 연속 이동 시간 수 ← 출어일 값들의 표준편차(날짜 간 변동) | F6: 민성·가설 E | H6: 가설 E(하루 리듬) | I6: 0.8
A7: 6 | B7: daytype_2_share | C7: 일 유형·이질성(G) | D7: 출어일 유형 | E7: 출어일 유형 2번 비중 (하루 피처 KMeans 8군집, 라벨 미사용) ← 선박 전체 기간에서 직접 계산 | F7: 가설 G | H7: 가설 G(이질성) | I7: 0.8
A8: 7 | B8: longest_streak_mean | C8: 하루 리듬·시각(E) | D8: 이동 블록 구조 | E8: 최장 연속 이동 시간 수 ← 출어일 값들의 평균 | F8: 민성·가설 E | H8: 가설 E(하루 리듬) | I8: 0.8
A9: 8 | B9: home_port_km | C9: 위치(LOC) | D9: 좌표 | E9: 모항↔최근접 공용항구 거리(km) ← 선박 전체 기간에서 직접 계산 | F9: 나연 | G9: O | I9: 0.8
A10: 9 | B10: mv_ks_straight_max_m_std | C10: 경로형태·직선투망(B) | D10: 직선 투망 형상 | E10: 5-step 최장 직선 이동(m, 회전 15° 미만 연속) = 투망 길이 추정 ← 출어일마다 이동 시간대 평균 → 출어일들의 표준편차(날짜 간 변동) | F10: 민성·가설 B | H10: 가설 B(직선 투망) | I10: 0.8
A11: 10 | B11: n_cells_200m_std | C11: 재방문·어장반복(A) | D11: 하루 내 재방문 | E11: 방문한 200m 격자 수 ← 출어일 값들의 표준편차(날짜 간 변동) | F11: 가설 A | H11: 가설 A(재방문) | I11: 0.8
A12: 11 | B12: mv_last_hour_std | C12: 하루 리듬·시각(E) | D12: 시작·종료 시각 | E12: 조업(이동) 종료 시각 ← 출어일 값들의 표준편차(날짜 간 변동) | F12: 나연 | H12: 가설 E(하루 리듬) | I12: 0.8
A13: 12 | B13: lon_c | C13: 위치(LOC) | D13: 좌표 | E13: 선박 대표 경도 (전체 시간 중앙값) ← 선박 전체 기간에서 직접 계산 | F13: 공통 | G13: O | I13: 0.6
A14: 13 | B14: fh_pca_elong_q90 | C14: 경로형태·직선투망(B) | D14: 직선 투망 형상 | E14: PCA 연신율 log(1+λ1/λ2): 직선 모양일수록 큼 ← 조업 시간대 1시간 값들의 선박별 90% 분위 | F14: 가설 B | H14: 가설 B(직선 투망) | I14: 0.6
A15: 14 | B15: fh_turn_mean_q90 | C15: 방향·회전(D) | D15: 회전각 | E15: 회전각 평균(°) ← 조업 시간대 1시간 값들의 선박별 90% 분위 | F15: 공통 | I15: 0.6
A16: 15 | B16: revisit_cell_ratio_std | C16: 재방문·어장반복(A) | D16: 하루 내 재방문 | E16: 200m 격자 중 여러 시간대에 방문한 칸 비율 ← 출어일 값들의 표준편차(날짜 간 변동) | F16: 가설 A | H16: 가설 A(재방문) | I16: 0.6
A17: 16 | B17: mv_share_night_mean | C17: 하루 리듬·시각(E) | D17: 시간대 비중 | E17: 이동 시간 중 밤(18~23시) 비중 ← 출어일 값들의 평균 | F17: 나연 | I17: 0.6
A18: 17 | B18: revisit_cell_ratio_mean | C18: 재방문·어장반복(A) | D18: 하루 내 재방문 | E18: 200m 격자 중 여러 시간대에 방문한 칸 비율 ← 출어일 값들의 평균 | F18: 가설 A | H18: 가설 A(재방문) | I18: 0.6
A19: 18 | B19: fh_pca_elong_q50 | C19: 경로형태·직선투망(B) | D19: 직선 투망 형상 | E19: PCA 연신율 log(1+λ1/λ2): 직선 모양일수록 큼 ← 조업 시간대 1시간 값들의 선박별 중앙값 | F19: 가설 B | H19: 가설 B(직선 투망) | I19: 0.6
A20: 19 | B20: top3_cell_share_median | C20: 재방문·어장반복(A) | D20: 하루 내 재방문 | E20: 상위 3칸 체류 비중 ← 출어일 값들의 중앙값 | F20: 가설 A | H20: 가설 A(재방문) | I20: 0.6
A21: 20 | B21: inter_hour_jump_med_km_median | C21: 속도 구조(C) | D21: 시간대 간 점프 | E21: 연속 시간대 끝→다음 시작 거리 중앙값(km) ← 출어일 값들의 중앙값 | F21: 민성 | I21: 0.6
A22: 21 | B22: moving_days_per_month | C22: 시간 사용·항차 | D22: 출어 활동량 | E22: 월평균 출어일 ← 선박 전체 기간에서 직접 계산 | F22: 나연 | I22: 0.6
A23: 22 | B23: home_lon | C23: 위치(LOC) | D23: 좌표 | E23: 모항 경도 ← 선박 전체 기간에서 직접 계산 | F23: 민성 | G23: O | I23: 0.4
A24: 23 | B24: dist_day_km_std | C24: 이동량·공간범위 | D24: 이동거리 | E24: 하루 평활 이동거리(km) ← 출어일 값들의 표준편차(날짜 간 변동) | F24: 나연·지유 | H24: 가설 G(이질성: 날짜 간 표준편차) | I24: 0.4
A25: 24 | B25: home_km_max_mean | C25: 이동량·공간범위 | D25: 모항·항구 거리 | E25: 모항에서 최대 거리(km) ← 출어일 값들의 평균 | F25: 민성·나연 | I25: 0.4
A26: 25 | B26: fishing_night_share | C26: 하루 리듬·시각(E) | D26: 시간대 비중 | E26: 조업 시간대 중 야간 비율 ← 선박 전체 기간에서 직접 계산 | F26: 민성 | I26: 0.4
A27: 26 | B27: season_m3_share | C27: 계절(H) | D27: 월별 출어 | E27: 3월 출어일 비중 ← 선박 전체 기간에서 직접 계산 | F27: 가설 H | H27: 가설 H(계절) | I27: 0.4
A28: 27 | B28: mv_last_hour_mean | C28: 하루 리듬·시각(E) | D28: 시작·종료 시각 | E28: 조업(이동) 종료 시각 ← 출어일 값들의 평균 | F28: 나연 | I28: 0.4
A29: 28 | B29: fh_n_stays_q90 | C29: 체류점 | D29: 체류점 | E29: 체류점 횟수 (반경 30m 안에 3점 이상 머묾) ← 조업 시간대 1시간 값들의 선박별 90% 분위 | F29: 민성 | H29: 가설 관련 | I29: 0.4
A30: 29 | B30: mv_seg_sinuosity_mean_median | C30: 경로형태·직선투망(B) | D30: 직진도·구불거림 | E30: 구간별 구불거림 평균 (변위 100m 이상 구간) ← 출어일마다 이동 시간대 평균 → 출어일들의 중앙값 | F30: 지유 | I30: 0.4
A31: 30 | B31: mv_pca_elong_median | C31: 경로형태·직선투망(B) | D31: 직선 투망 형상 | E31: PCA 연신율 log(1+λ1/λ2): 직선 모양일수록 큼 ← 출어일마다 이동 시간대 평균 → 출어일들의 중앙값 | F31: 가설 B | H31: 가설 B(직선 투망) | I31: 0.4

Sheet 일단위_MIL
A1: 피처명 | B1: 대분류 | C1: 세부 구분 | D1: 설명 | E1: 출처 | F1: 위치(LOC) | G1: MIL Pool A | H1: MIL Pool B
A2: n_hours | B2: 시간 사용·항차 | C2: 출어 활동량 | D2: 하루 기록 시간대 수 | E2: 나연·민성 | G2: O | H2: O
A3: first_hour | B3: 하루 리듬·시각(E) | C3: 시작·종료 시각 | D3: 첫 기록 시각 | E3: 민성·지유 | G3: O | H3: O
A4: last_hour | B4: 하루 리듬·시각(E) | C4: 시작·종료 시각 | D4: 마지막 기록 시각 | E4: 민성·지유 | G4: O | H4: O
A5: n_moving_hours | B5: 시간 사용·항차 | C5: 출어 활동량 | D5: 이동 시간대 수 | E5: 나연 | G5: O | H5: O
A6: stationary_ratio | B6: 시간 사용·항차 | C6: 상태별 시간 비율 | D6: 정박 시간대 비율 | E6: 지유 | G6: O | H6: O
A7: n_points_day | B7: 품질·기록량 | C7: 기록량 | D7: 하루 점 수 | E7: 나연 | G7: O | H7: O
A8: n_segments_mean | B8: 품질·기록량 | C8: 기록량 | D8: 시간당 평균 구간 수 | E8: 나연 | G8: O | H8: O
A9: frac_stop_mean | B9: 속도 구조(C) | C9: 속도 구간 비율 | D9: 평균 정지 비율 | E9: 나연 | G9: O | H9: O
A10: n_jumps_day | B10: 품질·기록량 | C10: GPS 튐·정제 | D10: 하루 15km 초과 점프 수 | E10: 나연 | G10: O | H10: O
A11: home_km_max | B11: 이동량·공간범위 | C11: 모항·항구 거리 | D11: 모항에서 최대 거리(km) | E11: 민성·나연 | G11: O | H11: O
A12: home_km_mean | B12: 이동량·공간범위 | C12: 모항·항구 거리 | D12: 모항에서 평균 거리(km) | E12: 나연 | G12: O | H12: O
A13: port_km_mean | B13: 이동량·공간범위 | C13: 모항·항구 거리 | D13: 최근접 공용항구까지 평균 거리(km) | E13: 나연 | G13: O | H13: O
... A29: mv_last_hour | B29: 하루 리듬·시각(E) | C29: 시작·종료 시각 | D29: 조업(이동) 종료 시각 | E29: 나연 | G29: O | H29: O
A30: lon_c | B30: 위치(LOC) | C30: 좌표 | D30: 하루 중심 경도 | E30: 나연 | F30: O | H30: O
A31: lat_c | B31: 위치(LOC) | C31: 좌표 | D31: 하루 중심 위도 | E31: 나연 | F31: O | H31: O
A32: lon_start | B32: 위치(LOC) | C32: 좌표 | D32: 하루 시작 경도 | E32: 나연 | F32: O | H32: O
A33: lat_start | B33: 위치(LOC) | C33: 좌표 | D33: 하루 시작 위도 | E33: 나연 | F33: O | H33: O
A34: lon_end | B34: 위치(LOC) | C34: 좌표 | D34: 하루 끝 경도 | E34: 나연 | F34: O | H34: O
A35: lat_end | B35: 위치(LOC) | C35: 좌표 | D35: 하루 끝 위도 | E35: 나연 | F35: O | H35: O
A36: home_km_start | B36: 이동량·공간범위 | C36: 모항·항구 거리 | D36: 하루 시작 위치의 모항 거리 | E36: 나연 | G36: O | H36: O
A37: home_km_end | B37: 이동량·공간범위 | C37: 모항·항구 거리 | D37: 하루 끝 위치의 모항 거리 | E37: 나연 | G37: O | H37: O
A38: month | B38: 계절(H) | C38: 월별 출어 | D38: 월 | E38: 민성 | G38: O | H38: O
A39: moving_ratio | B39: 시간 사용·항차 | C39: 출어 활동량 | D39: 이동 시간대 비율 | E39: 나연 | G39: O | H39: O
A40: active_span_h | B40: 하루 리듬·시각(E) | C40: 조업 시간 폭 | D40: 첫~마지막 기록 시간 폭 | E40: 나연 | G40: O | H40: O
A41: mv_span_h | B41: 하루 리듬·시각(E) | C41: 조업 시간 폭 | D41: 조업 시간 폭 (첫~마지막 이동) | E41: 나연·민성 | G41: O | H41: O
A42: dist_day_km | B42: 이동량·공간범위 | C42: 이동거리 | D42: 하루 평활 이동거리(km) | E42: 나연·지유 | G42: O | H42: O
A43: dist_raw_day_km | B43: 이동량·공간범위 | C43: 이동거리 | D43: 하루 원거리(km) | E43: 나연 | G43: O | H43: O
A44: jump_share_day | B44: 품질·기록량 | C44: GPS 튐·정제 | D44: 튐 비중 = 1 − 평활/원거리 | E44: 나연 | G44: O | H44: O
A45: day_net_disp_km | B45: 이동량·공간범위 | C45: 변위·이격 | D45: 하루 시작→끝 변위(km) | E45: 나연 | G45: O | H45: O
A46: day_straightness | B46: 경로형태·직선투망(B) | C46: 직진도·구불거림 | D46: 하루 직진도 = 변위/거리 | E46: 가설 B | G46: O | H46: O
A47: returned_to_port | B47: 시간 사용·항차 | C47: 항차(출항~귀항) | D47: 귀항 여부 | E47: 나연 | G47: O | H47: O
... A96: mv_bin_dispersion_m | B96: 품질·기록량 | C96: GPS 튐·정제 | D96: 그날 이동 시간대 평균: 10분 구간 내 점 흩어짐(m) | E96: 나연 | G96: O | H96: O
A97: mv_lon_c | B97: 위치(LOC) | C97: 좌표 | D97: 이동 시간대 대표 경도 | E97: 나연 | F97: O | H97: O
A98: mv_lat_c | B98: 위치(LOC) | C98: 좌표 | D98: 이동 시간대 대표 위도 | E98: 나연 | F98: O | H98: O
A99: return_after_absence | B99: 재방문·어장반복(A) | C99: 하루 내 재방문 | D99: 200m 격자를 2시간 이상 떠났다 돌아온 횟수 | E99: 가설 A | G99: O | H99: O
A100: revisit_cell_ratio | B100: 재방문·어장반복(A) | C100: 하루 내 재방문 | D100: 200m 격자 중 여러 시간대에 방문한 칸 비율 | E100: 가설 A | G100: O | H100: O
A101: n_cells_200m | B101: 재방문·어장반복(A) | C101: 하루 내 재방문 | D101: 방문한 200m 격자 수 | E101: 가설 A | G101: O | H101: O
A102: top3_cell_share | B102: 재방문·어장반복(A) | C102: 하루 내 재방문 | D102: 상위 3칸 체류 비중 | E102: 가설 A | G102: O | H102: O

Sheet 시간단위_L1
A1: 피처명 | B1: 대분류 | C1: 세부 구분 | D1: 설명 | E1: 출처
A2: n_points_raw | B2: 품질·기록량 | C2: 기록량 | D2: 원본 GPS 점 수 | E2: 지유·나연·진우
A3: n_points | B3: 품질·기록량 | C3: 기록량 | D3: 튐 제거 후 점 수 | E3: 지유·나연·진우
A4: n_segments | B4: 품질·기록량 | C4: 기록량 | D4: MultiLineString 구간 수 (신호 끊김+1) | E4: 지유·나연·진우
A5: gap_count | B5: 품질·기록량 | C5: 기록량 | D5: 관측 끊김 횟수 | E5: 지유
A6: pts_per_seg | B6: 품질·기록량 | C6: 기록량 | D6: 구간당 평균 점 수 | E6: 지유
A7: uniq_pos_ratio | B7: 품질·기록량 | C7: 기록량 | D7: 고유 위치(10m 격자) 비율: 낮으면 제자리 | E7: 나연
A8: n_spikes | B8: 품질·기록량 | C8: GPS 튐·정제 | D8: 제거된 A→B→A 튐 점 수 | E8: 나연·지유
A9: spike_ratio | B9: 품질·기록량 | C9: GPS 튐·정제 | D9: 튐 점 비율 | E9: 나연·지유
A10: n_jumps | B10: 품질·기록량 | C10: GPS 튐·정제 | D10: 15km 초과 점프 수 | E10: 나연
A11: n_bin_spikes | B11: 품질·기록량 | C11: GPS 튐·정제 | D11: 10분 구간 수준 튐 수 | E11: 나연
A12: n_bin_jumps | B12: 품질·기록량 | C12: GPS 튐·정제 | D12: 10분 구간 간 7km 초과 점프 수 | E12: 나연
... A93: is_stationary | B93: 시간 사용·항차 | C93: 상태별 시간 비율 | D93: 정박 여부 (평활 범위 <100m) | E93: 나연
